Workbook

Sheet About
A1: Barangay Service Request Analysis (April–September 2026)
A2: Project 2: Data / Database Project
A4: Purpose: Analyze barangay service requests to find the most common concerns, monthly trends, problem areas, resolution speed, and resident satisfaction.
A6: Data source
A7: Simulated sample data (217 requests) created for practice, modeled on the AI-Assisted Barangay Service Request System (Project 1). It does not contain real residents or real barangay records.
A9: Columns in the Data sheet
A10: request_id – unique request number
A11: date_submitted – date the resident submitted the request
A12: zone – area of the barangay (Zone 1 to Zone 6)
A13: category – auto-detected category from the system
A14: status – Pending, In Progress, or Resolved
A15: date_resolved – date the request was resolved (blank if not yet resolved)
... A24: AI use: AI generated the sample dataset and helped build the formulas and charts; I verified the results and wrote the interpretations.

Sheet Data
A1: request_id | B1: date_submitted | C1: zone | D1: category | E1: status | F1: date_resolved | G1: days_to_resolve | H1: satisfaction_rating | I1: month
A2: REQ-0001 | B2: 46114 | C2: Zone 4 | D2: Water Supply | E2: In Progress | I2: =TEXT(B2,"YYYY-MM") -> 2026-04
A3: REQ-0002 | B3: 46115 | C3: Zone 4 | D3: Health | E3: Resolved | F3: 46119 | G3: 4 | H3: 3 | I3: =TEXT(B3,"YYYY-MM") -> 2026-04
A4: REQ-0003 | B4: 46116 | C4: Zone 4 | D4: Documents / Certificates | E4: Resolved | F4: 46117 | G4: 1 | H4: 2 | I4: =TEXT(B4,"YYYY-MM") -> 2026-04
A5: REQ-0004 | B5: 46117 | C5: Zone 3 | D5: Documents / Certificates | E5: Resolved | F5: 46120 | G5: 3 | H5: 2 | I5: =TEXT(B5,"YYYY-MM") -> 2026-04
A6: REQ-0005 | B6: 46118 | C6: Zone 6 | D6: Streetlight / Electrical | E6: Resolved | F6: 46126 | G6: 8 | H6: 5 | I6: =TEXT(B6,"YYYY-MM") -> 2026-04
A7: REQ-0006 | B7: 46119 | C7: Zone 5 | D7: Peace and Order | E7: Resolved | F7: 46120 | G7: 1 | H7: 3 | I7: =TEXT(B7,"YYYY-MM") -> 2026-04
A8: REQ-0007 | B8: 46119 | C8: Zone 6 | D8: Road / Infrastructure | E8: Resolved | F8: 46144 | G8: 25 | H8: 4 | I8: =TEXT(B8,"YYYY-MM") -> 2026-04
A9: REQ-0008 | B9: 46120 | C9: Zone 4 | D9: Streetlight / Electrical | E9: Resolved | F9: 46129 | G9: 9 | H9: 3 | I9: =TEXT(B9,"YYYY-MM") -> 2026-04
A10: REQ-0009 | B10: 46122 | C10: Zone 5 | D10: Water Supply | E10: Resolved | F10: 46128 | G10: 6 | H10: 2 | I10: =TEXT(B10,"YYYY-MM") -> 2026-04
A11: REQ-0010 | B11: 46123 | C11: Zone 4 | D11: Streetlight / Electrical | E11: Resolved | F11: 46133 | G11: 10 | H11: 4 | I11: =TEXT(B11,"YYYY-MM") -> 2026-04
A12: REQ-0011 | B12: 46123 | C12: Zone 5 | D12: Water Supply | E12: Resolved | F12: 46131 | G12: 8 | H12: 3 | I12: =TEXT(B12,"YYYY-MM") -> 2026-04
A13: REQ-0012 | B13: 46125 | C13: Zone 1 | D13: Road / Infrastructure | E13: Resolved | F13: 46139 | G13: 14 | H13: 2 | I13: =TEXT(B13,"YYYY-MM") -> 2026-04
A14: REQ-0013 | B14: 46125 | C14: Zone 5 | D14: Peace and Order | E14: Resolved | F14: 46128 | G14: 3 | H14: 3 | I14: =TEXT(B14,"YYYY-MM") -> 2026-04
... A19: REQ-0018 | B19: 46130 | C19: Zone 6 | D19: Streetlight / Electrical | E19: Resolved | F19: 46134 | G19: 4 | H19: 4 | I19: =TEXT(B19,"YYYY-MM") -> 2026-04
A20: REQ-0019 | B20: 46131 | C20: Zone 6 | D20: Streetlight / Electrical | E20: In Progress | I20: =TEXT(B20,"YYYY-MM") -> 2026-04
A21: REQ-0020 | B21: 46131 | C21: Zone 3 | D21: Documents / Certificates | E21: Resolved | F21: 46132 | G21: 1 | H21: 5 | I21: =TEXT(B21,"YYYY-MM") -> 2026-04
A22: REQ-0021 | B22: 46132 | C22: Zone 4 | D22: Garbage / Sanitation | E22: Resolved | F22: 46140 | G22: 8 | H22: 4 | I22: =TEXT(B22,"YYYY-MM") -> 2026-04
A23: REQ-0022 | B23: 46135 | C23: Zone 6 | D23: Water Supply | E23: Resolved | F23: 46137 | G23: 2 | H23: 3 | I23: =TEXT(B23,"YYYY-MM") -> 2026-04
A24: REQ-0023 | B24: 46137 | C24: Zone 3 | D24: Garbage / Sanitation | E24: Resolved | F24: 46143 | G24: 6 | H24: 3 | I24: =TEXT(B24,"YYYY-MM") -> 2026-04
A25: REQ-0024 | B25: 46137 | C25: Zone 3 | D25: Garbage / Sanitation | E25: Resolved | F25: 46146 | G25: 9 | H25: 5 | I25: =TEXT(B25,"YYYY-MM") -> 2026-04
A26: REQ-0025 | B26: 46138 | C26: Zone 3 | D26: Garbage / Sanitation | E26: Resolved | F26: 46144 | G26: 6 | H26: 3 | I26: =TEXT(B26,"YYYY-MM") -> 2026-04
A27: REQ-0026 | B27: 46138 | C27: Zone 5 | D27: Health | E27: Resolved | F27: 46143 | G27: 5 | H27: 2 | I27: =TEXT(B27,"YYYY-MM") -> 2026-04
A28: REQ-0027 | B28: 46139 | C28: Zone 2 | D28: Water Supply | E28: In Progress | I28: =TEXT(B28,"YYYY-MM") -> 2026-04
A29: REQ-0028 | B29: 46140 | C29: Zone 1 | D29: Documents / Certificates | E29: Resolved | F29: 46142 | G29: 2 | H29: 4 | I29: =TEXT(B29,"YYYY-MM") -> 2026-04
A30: REQ-0029 | B30: 46143 | C30: Zone 5 | D30: Road / Infrastructure | E30: Resolved | F30: 46164 | G30: 21 | H30: 1 | I30: =TEXT(B30,"YYYY-MM") -> 2026-05
A31: REQ-0030 | B31: 46143 | C31: Zone 4 | D31: Health | E31: Resolved | F31: 46145 | G31: 2 | H31: 4 | I31: =TEXT(B31,"YYYY-MM") -> 2026-05
A32: REQ-0031 | B32: 46144 | C32: Zone 3 | D32: Water Supply | E32: Resolved | F32: 46147 | G32: 3 | H32: 2 | I32: =TEXT(B32,"YYYY-MM") -> 2026-05
A33: REQ-0032 | B33: 46145 | C33: Zone 4 | D33: Garbage / Sanitation | E33: Resolved | F33: 46149 | G33: 4 | H33: 4 | I33: =TEXT(B33,"YYYY-MM") -> 2026-05
A34: REQ-0033 | B34: 46147 | C34: Zone 4 | D34: Documents / Certificates | E34: Resolved | F34: 46149 | G34: 2 | H34: 4 | I34: =TEXT(B34,"YYYY-MM") -> 2026-05
A35: REQ-0034 | B35: 46148 | C35: Zone 2 | D35: Peace and Order | E35: Resolved | F35: 46150 | G35: 2 | H35: 5 | I35: =TEXT(B35,"YYYY-MM") -> 2026-05
A36: REQ-0035 | B36: 46149 | C36: Zone 4 | D36: Streetlight / Electrical | E36: Resolved | F36: 46153 | G36: 4 | H36: 3 | I36: =TEXT(B36,"YYYY-MM") -> 2026-05
A37: REQ-0036 | B37: 46150 | C37: Zone 4 | D37: Streetlight / Electrical | E37: Resolved | F37: 46159 | G37: 9 | H37: 1 | I37: =TEXT(B37,"YYYY-MM") -> 2026-05
A38: REQ-0037 | B38: 46151 | C38: Zone 1 | D38: Water Supply | E38: Resolved | F38: 46159 | G38: 8 | H38: 2 | I38: =TEXT(B38,"YYYY-MM") -> 2026-05
A39: REQ-0038 | B39: 46151 | C39: Zone 2 | D39: Garbage / Sanitation | E39: In Progress | I39: =TEXT(B39,"YYYY-MM") -> 2026-05
A40: REQ-0039 | B40: 46152 | C40: Zone 3 | D40: Peace and Order | E40: In Progress | I40: =TEXT(B40,"YYYY-MM") -> 2026-05
A41: REQ-0040 | B41: 46153 | C41: Zone 3 | D41: Documents / Certificates | E41: Resolved | F41: 46156 | G41: 3 | H41: 3 | I41: =TEXT(B41,"YYYY-MM") -> 2026-05
A42: REQ-0041 | B42: 46155 | C42: Zone 4 | D42: Peace and Order | E42: Resolved | F42: 46157 | G42: 2 | H42: 4 | I42: =TEXT(B42,"YYYY-MM") -> 2026-05
A43: REQ-0042 | B43: 46155 | C43: Zone 1 | D43: Peace and Order | E43: Resolved | F43: 46158 | G43: 3 | H43: 2 | I43: =TEXT(B43,"YYYY-MM") -> 2026-05
A44: REQ-0043 | B44: 46158 | C44: Zone 2 | D44: Peace and Order | E44: Resolved | F44: 46159 | G44: 1 | H44: 3 | I44: =TEXT(B44,"YYYY-MM") -> 2026-05
...

Sheet Q1 Category
A1: Q1. Which concern is reported the most?
A3: Category | B3: Requests | C3: Share of total
A4: Garbage / Sanitation | B4: =COUNTIF(Data!$D$2:$D$218,A4) -> 63 | C4: =B4/$B$12 -> 0.29032258
A5: Documents / Certificates | B5: =COUNTIF(Data!$D$2:$D$218,A5) -> 35 | C5: =B5/$B$12 -> 0.16129032
A6: Streetlight / Electrical | B6: =COUNTIF(Data!$D$2:$D$218,A6) -> 30 | C6: =B6/$B$12 -> 0.13824885
A7: Road / Infrastructure | B7: =COUNTIF(Data!$D$2:$D$218,A7) -> 28 | C7: =B7/$B$12 -> 0.12903226
A8: Water Supply | B8: =COUNTIF(Data!$D$2:$D$218,A8) -> 21 | C8: =B8/$B$12 -> 0.096774194
A9: Peace and Order | B9: =COUNTIF(Data!$D$2:$D$218,A9) -> 19 | C9: =B9/$B$12 -> 0.087557604
A10: Health | B10: =COUNTIF(Data!$D$2:$D$218,A10) -> 14 | C10: =B10/$B$12 -> 0.064516129
A11: Others | B11: =COUNTIF(Data!$D$2:$D$218,A11) -> 7 | C11: =B11/$B$12 -> 0.032258065
A12: Total | B12: =SUM(B4:B11) -> 217 | C12: =SUM(C4:C11) -> 1
A14: Formula: =COUNTIF(Data!D:D, category). Share = requests ÷ total.

Sheet Q2 Monthly
A1: Q2. How do requests change per month?
A3: Month key | B3: Month | C3: Total requests | D3: Garbage / Sanitation | E3: Road / Infrastructure | F3: Health | G3: Rain-related total | H3: Water Supply
A4: 2026-04 | B4: Apr 2026 | C4: =COUNTIF(Data!$I$2:$I$218,A4) -> 28 | D4: =COUNTIFS(Data!$I$2:$I$218,A4,Data!$D$2:$D$218,"Garbage / Sanitation") -> 5 | E4: =COUNTIFS(Data!$I$2:$I$218,A4,Data!$D$2:$D$218,"Road / Infrastructure") -> 2 | F4: =COUNTIFS(Data!$I$2:$I$218,A4,Data!$D$2:$D$218,"Health") -> 2 | G4: =SUM(D4:F4) -> 9 | H4: =COUNTIFS(Data!$I$2:$I$218,A4,Data!$D$2:$D$218,"Water Supply") -> 6
A5: 2026-05 | B5: May 2026 | C5: =COUNTIF(Data!$I$2:$I$218,A5) -> 28 | D5: =COUNTIFS(Data!$I$2:$I$218,A5,Data!$D$2:$D$218,"Garbage / Sanitation") -> 5 | E5: =COUNTIFS(Data!$I$2:$I$218,A5,Data!$D$2:$D$218,"Road / Infrastructure") -> 3 | F5: =COUNTIFS(Data!$I$2:$I$218,A5,Data!$D$2:$D$218,"Health") -> 2 | G5: =SUM(D5:F5) -> 10 | H5: =COUNTIFS(Data!$I$2:$I$218,A5,Data!$D$2:$D$218,"Water Supply") -> 6
A6: 2026-06 | B6: Jun 2026 | C6: =COUNTIF(Data!$I$2:$I$218,A6) -> 33 | D6: =COUNTIFS(Data!$I$2:$I$218,A6,Data!$D$2:$D$218,"Garbage / Sanitation") -> 9 | E6: =COUNTIFS(Data!$I$2:$I$218,A6,Data!$D$2:$D$218,"Road / Infrastructure") -> 3 | F6: =COUNTIFS(Data!$I$2:$I$218,A6,Data!$D$2:$D$218,"Health") -> 2 | G6: =SUM(D6:F6) -> 14 | H6: =COUNTIFS(Data!$I$2:$I$218,A6,Data!$D$2:$D$218,"Water Supply") -> 1
A7: 2026-07 | B7: Jul 2026 | C7: =COUNTIF(Data!$I$2:$I$218,A7) -> 49 | D7: =COUNTIFS(Data!$I$2:$I$218,A7,Data!$D$2:$D$218,"Garbage / Sanitation") -> 18 | E7: =COUNTIFS(Data!$I$2:$I$218,A7,Data!$D$2:$D$218,"Road / Infrastructure") -> 7 | F7: =COUNTIFS(Data!$I$2:$I$218,A7,Data!$D$2:$D$218,"Health") -> 2 | G7: =SUM(D7:F7) -> 27 | H7: =COUNTIFS(Data!$I$2:$I$218,A7,Data!$D$2:$D$218,"Water Supply") -> 2
A8: 2026-08 | B8: Aug 2026 | C8: =COUNTIF(Data!$I$2:$I$218,A8) -> 38 | D8: =COUNTIFS(Data!$I$2:$I$218,A8,Data!$D$2:$D$218,"Garbage / Sanitation") -> 9 | E8: =COUNTIFS(Data!$I$2:$I$218,A8,Data!$D$2:$D$218,"Road / Infrastructure") -> 9 | F8: =COUNTIFS(Data!$I$2:$I$218,A8,Data!$D$2:$D$218,"Health") -> 3 | G8: =SUM(D8:F8) -> 21 | H8: =COUNTIFS(Data!$I$2:$I$218,A8,Data!$D$2:$D$218,"Water Supply") -> 1
A9: 2026-09 | B9: Sep 2026 | C9: =COUNTIF(Data!$I$2:$I$218,A9) -> 41 | D9: =COUNTIFS(Data!$I$2:$I$218,A9,Data!$D$2:$D$218,"Garbage / Sanitation") -> 17 | E9: =COUNTIFS(Data!$I$2:$I$218,A9,Data!$D$2:$D$218,"Road / Infrastructure") -> 4 | F9: =COUNTIFS(Data!$I$2:$I$218,A9,Data!$D$2:$D$218,"Health") -> 3 | G9: =SUM(D9:F9) -> 24 | H9: =COUNTIFS(Data!$I$2:$I$218,A9,Data!$D$2:$D$218,"Water Supply") -> 5
B10: Total | C10: =SUM(C4:C9) -> 217 | D10: =SUM(D4:D9) -> 63 | E10: =SUM(E4:E9) -> 28 | F10: =SUM(F4:F9) -> 14 | G10: =SUM(G4:G9) -> 105 | H10: =SUM(H4:H9) -> 21
B12: Dry season (Apr–Jun) | C12: =SUM(C4:C6) -> 89 | G12: =SUM(G4:G6) -> 33 | H12: =SUM(H4:H6) -> 13
B13: Rainy season (Jul–Sep) | C13: =SUM(C7:C9) -> 128 | G13: =SUM(G7:G9) -> 72 | H13: =SUM(H7:H9) -> 8
B14: Change | C14: =(C13-C12)/C12 -> 0.43820225 | G14: =(G13-G12)/G12 -> 1.1818182 | H14: =(H13-H12)/H12 -> -0.38461538
A16: Rain-related = Garbage / Sanitation + Road / Infrastructure + Health (flooding, clogged drainage, dengue). Formulas: COUNTIF and COUNTIFS on the month helper column.

Sheet Q3 Zone
A1: Q3. Which zone has the most requests?
A3: Zone | B3: Total requests | C3: Garbage / Sanitation | D3: Garbage share of zone | E3: Streetlight / Electrical
A4: Zone 1 | B4: =COUNTIF(Data!$C$2:$C$218,A4) -> 29 | C4: =COUNTIFS(Data!$C$2:$C$218,A4,Data!$D$2:$D$218,"Garbage / Sanitation") -> 9 | D4: =C4/B4 -> 0.31034483 | E4: =COUNTIFS(Data!$C$2:$C$218,A4,Data!$D$2:$D$218,"Streetlight / Electrical") -> 2
A5: Zone 2 | B5: =COUNTIF(Data!$C$2:$C$218,A5) -> 29 | C5: =COUNTIFS(Data!$C$2:$C$218,A5,Data!$D$2:$D$218,"Garbage / Sanitation") -> 5 | D5: =C5/B5 -> 0.17241379 | E5: =COUNTIFS(Data!$C$2:$C$218,A5,Data!$D$2:$D$218,"Streetlight / Electrical") -> 5
A6: Zone 3 | B6: =COUNTIF(Data!$C$2:$C$218,A6) -> 53 | C6: =COUNTIFS(Data!$C$2:$C$218,A6,Data!$D$2:$D$218,"Garbage / Sanitation") -> 27 | D6: =C6/B6 -> 0.50943396 | E6: =COUNTIFS(Data!$C$2:$C$218,A6,Data!$D$2:$D$218,"Streetlight / Electrical") -> 4
A7: Zone 4 | B7: =COUNTIF(Data!$C$2:$C$218,A7) -> 38 | C7: =COUNTIFS(Data!$C$2:$C$218,A7,Data!$D$2:$D$218,"Garbage / Sanitation") -> 8 | D7: =C7/B7 -> 0.21052632 | E7: =COUNTIFS(Data!$C$2:$C$218,A7,Data!$D$2:$D$218,"Streetlight / Electrical") -> 5
A8: Zone 5 | B8: =COUNTIF(Data!$C$2:$C$218,A8) -> 31 | C8: =COUNTIFS(Data!$C$2:$C$218,A8,Data!$D$2:$D$218,"Garbage / Sanitation") -> 6 | D8: =C8/B8 -> 0.19354839 | E8: =COUNTIFS(Data!$C$2:$C$218,A8,Data!$D$2:$D$218,"Streetlight / Electrical") -> 5
A9: Zone 6 | B9: =COUNTIF(Data!$C$2:$C$218,A9) -> 37 | C9: =COUNTIFS(Data!$C$2:$C$218,A9,Data!$D$2:$D$218,"Garbage / Sanitation") -> 8 | D9: =C9/B9 -> 0.21621622 | E9: =COUNTIFS(Data!$C$2:$C$218,A9,Data!$D$2:$D$218,"Streetlight / Electrical") -> 9
A10: Total | B10: =SUM(B4:B9) -> 217 | C10: =SUM(C4:C9) -> 63 | D10: =C10/B10 -> 0.29032258 | E10: =SUM(E4:E9) -> 30
A12: Zone 3 share of ALL garbage requests: | D12: =C6/C10 -> 0.42857143
A14: Formulas: =COUNTIF(Data!C:C, zone) and =COUNTIFS(Data!C:C, zone, Data!D:D, "Garbage / Sanitation").

Sheet Q4 Resolution
A1: Q4. Which category takes the longest to resolve?
A3: Category | B3: Resolved requests | C3: Average days to resolve | D3: Longest (days)
A4: Road / Infrastructure | B4: =COUNTIFS(Data!$D$2:$D$218,A4,Data!$E$2:$E$218,"Resolved") -> 26 | C4: =AVERAGEIFS(Data!$G$2:$G$218,Data!$D$2:$D$218,A4,Data!$E$2:$E$218,"Resolved") -> 17.153846 | D4: =_xlfn.MAXIFS(Data!$G$2:$G$218,Data!$D$2:$D$218,A4,Data!$E$2:$E$218,"Resolved") -> 25
A5: Streetlight / Electrical | B5: =COUNTIFS(Data!$D$2:$D$218,A5,Data!$E$2:$E$218,"Resolved") -> 28 | C5: =AVERAGEIFS(Data!$G$2:$G$218,Data!$D$2:$D$218,A5,Data!$E$2:$E$218,"Resolved") -> 7.2142857 | D5: =_xlfn.MAXIFS(Data!$G$2:$G$218,Data!$D$2:$D$218,A5,Data!$E$2:$E$218,"Resolved") -> 12
A6: Others | B6: =COUNTIFS(Data!$D$2:$D$218,A6,Data!$E$2:$E$218,"Resolved") -> 6 | C6: =AVERAGEIFS(Data!$G$2:$G$218,Data!$D$2:$D$218,A6,Data!$E$2:$E$218,"Resolved") -> 5.5 | D6: =_xlfn.MAXIFS(Data!$G$2:$G$218,Data!$D$2:$D$218,A6,Data!$E$2:$E$218,"Resolved") -> 10
A7: Garbage / Sanitation | B7: =COUNTIFS(Data!$D$2:$D$218,A7,Data!$E$2:$E$218,"Resolved") -> 57 | C7: =AVERAGEIFS(Data!$G$2:$G$218,Data!$D$2:$D$218,A7,Data!$E$2:$E$218,"Resolved") -> 5.4736842 | D7: =_xlfn.MAXIFS(Data!$G$2:$G$218,Data!$D$2:$D$218,A7,Data!$E$2:$E$218,"Resolved") -> 9
A8: Water Supply | B8: =COUNTIFS(Data!$D$2:$D$218,A8,Data!$E$2:$E$218,"Resolved") -> 17 | C8: =AVERAGEIFS(Data!$G$2:$G$218,Data!$D$2:$D$218,A8,Data!$E$2:$E$218,"Resolved") -> 4.7058824 | D8: =_xlfn.MAXIFS(Data!$G$2:$G$218,Data!$D$2:$D$218,A8,Data!$E$2:$E$218,"Resolved") -> 8
A9: Health | B9: =COUNTIFS(Data!$D$2:$D$218,A9,Data!$E$2:$E$218,"Resolved") -> 13 | C9: =AVERAGEIFS(Data!$G$2:$G$218,Data!$D$2:$D$218,A9,Data!$E$2:$E$218,"Resolved") -> 3.3076923 | D9: =_xlfn.MAXIFS(Data!$G$2:$G$218,Data!$D$2:$D$218,A9,Data!$E$2:$E$218,"Resolved") -> 5
A10: Peace and Order | B10: =COUNTIFS(Data!$D$2:$D$218,A10,Data!$E$2:$E$218,"Resolved") -> 16 | C10: =AVERAGEIFS(Data!$G$2:$G$218,Data!$D$2:$D$218,A10,Data!$E$2:$E$218,"Resolved") -> 2.1875 | D10: =_xlfn.MAXIFS(Data!$G$2:$G$218,Data!$D$2:$D$218,A10,Data!$E$2:$E$218,"Resolved") -> 4
A11: Documents / Certificates | B11: =COUNTIFS(Data!$D$2:$D$218,A11,Data!$E$2:$E$218,"Resolved") -> 34 | C11: =AVERAGEIFS(Data!$G$2:$G$218,Data!$D$2:$D$218,A11,Data!$E$2:$E$218,"Resolved") -> 2 | D11: =_xlfn.MAXIFS(Data!$G$2:$G$218,Data!$D$2:$D$218,A11,Data!$E$2:$E$218,"Resolved") -> 3
A12: All categories | B12: =SUM(B4:B11) -> 197 | C12: =AVERAGEIFS(Data!$G$2:$G$218,Data!$E$2:$E$218,"Resolved") -> 6.1878173 | D12: =_xlfn.MAXIFS(Data!$G$2:$G$218,Data!$E$2:$E$218,"Resolved") -> 25
A14: Still open (Pending + In Progress): | C14: =COUNTIF(Data!$E$2:$E$218,"Pending")+COUNTIF(Data!$E$2:$E$218,"In Progress") -> 20
A16: Only Resolved requests are included. Formula: =AVERAGEIFS(Data!G:G, Data!D:D, category, Data!E:E, "Resolved").

Sheet Q5 Satisfaction
A1: Q5. Does faster resolution mean happier residents?
A3: Resolution time | B3: Min days | C3: Max days | D3: Resolved requests | E3: Average rating (1–5)
A4: 1–3 days | B4: 1 | C4: 3 | D4: =COUNTIFS(Data!$E$2:$E$218,"Resolved",Data!$G$2:$G$218,">="&B4,Data!$G$2:$G$218,"<="&C4) -> 78 | E4: =AVERAGEIFS(Data!$H$2:$H$218,Data!$E$2:$E$218,"Resolved",Data!$G$2:$G$218,">="&B4,Data!$G$2:$G$218,"<="&C4) -> 3.2051282
A5: 4–7 days | B5: 4 | C5: 7 | D5: =COUNTIFS(Data!$E$2:$E$218,"Resolved",Data!$G$2:$G$218,">="&B5,Data!$G$2:$G$218,"<="&C5) -> 62 | E5: =AVERAGEIFS(Data!$H$2:$H$218,Data!$E$2:$E$218,"Resolved",Data!$G$2:$G$218,">="&B5,Data!$G$2:$G$218,"<="&C5) -> 3.1612903
A6: 8–14 days | B6: 8 | C6: 14 | D6: =COUNTIFS(Data!$E$2:$E$218,"Resolved",Data!$G$2:$G$218,">="&B6,Data!$G$2:$G$218,"<="&C6) -> 41 | E6: =AVERAGEIFS(Data!$H$2:$H$218,Data!$E$2:$E$218,"Resolved",Data!$G$2:$G$218,">="&B6,Data!$G$2:$G$218,"<="&C6) -> 3.097561
A7: 15+ days | B7: 15 | C7: 999 | D7: =COUNTIFS(Data!$E$2:$E$218,"Resolved",Data!$G$2:$G$218,">="&B7,Data!$G$2:$G$218,"<="&C7) -> 16 | E7: =AVERAGEIFS(Data!$H$2:$H$218,Data!$E$2:$E$218,"Resolved",Data!$G$2:$G$218,">="&B7,Data!$G$2:$G$218,"<="&C7) -> 2.5
A8: All resolved | D8: =SUM(D4:D7) -> 197 | E8: =AVERAGEIFS(Data!$H$2:$H$218,Data!$E$2:$E$218,"Resolved") -> 3.1116751
A10: Drop in rating (15+ days vs 1–3 days): | E10: =E7-E4 -> -0.70512821
A12: Blue numbers are the day ranges you can change. Formula: =AVERAGEIFS(Data!H:H, Data!E:E, "Resolved", Data!G:G, ">="&min, Data!G:G, "<="&max).

Sheet Findings
A1: Key Findings and Recommendations
A3: Question | B3: What the data shows | C3: Recommendation
A4: 1. Most reported concern | B4: Garbage / Sanitation is the top concern with 63 of 217 requests (29%), almost twice the second-highest category, Documents / Certificates (35). | C4: Review the garbage collection schedule and add collection days where requests are highest.
A5: 2. Monthly trend | B5: Requests rose from 89 in the dry months (Apr–Jun) to 128 in the rainy months (Jul–Sep), a 44% increase. July was the busiest month (49). Rain-related requests (garbage, road, health) more than doubled, from 33 to 72 (+118%). Water Supply requests went the other way, mostly in April–May (dry season). | C5: Prepare before the rainy season: clear drainage and canals in June and plan extra road repair and dengue prevention activities.
A6: 3. Problem area | B6: Zone 3 has the most requests (53). About half of Zone 3's requests are about garbage (27 of 53), and Zone 3 alone accounts for 43% of all garbage requests. | C6: Prioritize Zone 3 for garbage collection, add trash bins, and post reminders about proper waste disposal.
A7: 4. Resolution speed | B7: The average resolution time is 6.2 days. Road / Infrastructure takes the longest at 17.2 days on average (up to 25 days), while Documents / Certificates take only 2.0 days. 20 requests are still open. | C7: Give residents an estimated completion time for road repairs and send status updates so they know the request is being handled.
A8: 5. Satisfaction | B8: Ratings stay around 3.1–3.2 when requests are resolved within 14 days, but drop to 2.5 when they take 15 days or more (a drop of 0.7). Speed matters most for long delays, not small differences of a few days. | C8: Set a target to resolve or update every request within 14 days, especially road and streetlight concerns.
A10: Note: Based on simulated sample data (217 requests, April–September 2026). Numbers come from the Q1–Q5 sheets.
A11: Limitation: Satisfaction ratings exist only for resolved requests; the 20 open requests are not rated yet.
